[2025-08-12 05:44:21,046] WARNING django.request - Unauthorized: /schedule/create-scheduled-rounds/
[2025-08-12 05:44:36,751] WARNING django.request - Bad Request: /schedule/create-scheduled-rounds/
[2025-08-12 05:45:38,764] WARNING django.request - Unauthorized: /schedule/view-patient-scheduled-rounds/19/
[2025-08-12 05:49:36,522] WARNING django.request - Unauthorized: /schedule/create-scheduled-rounds/
[2025-08-12 05:51:57,847] ERROR django.request - Internal Server Error: /schedule/create-scheduled-rounds/
Traceback (most recent call last):
  File "/usr/local/lib/python3.11/site-packages/asgiref/sync.py", line 489, in thread_handler
    raise exc_info[1]
  File "/usr/local/lib/python3.11/site-packages/django/core/handlers/exception.py", line 42, in inner
    response = await get_response(request)
               ^^^^^^^^^^^^^^^^^^^^^^^^^^^
  File "/usr/local/lib/python3.11/site-packages/asgiref/sync.py", line 489, in thread_handler
    raise exc_info[1]
  File "/usr/local/lib/python3.11/site-packages/django/core/handlers/base.py", line 253, in _get_response_async
    response = await wrapped_callback(
               ^^^^^^^^^^^^^^^^^^^^^^^
  File "/usr/local/lib/python3.11/site-packages/asgiref/sync.py", line 439, in __call__
    ret = await asyncio.shield(exec_coro)
          ^^^^^^^^^^^^^^^^^^^^^^^^^^^^^^^
  File "/usr/local/lib/python3.11/site-packages/asgiref/current_thread_executor.py", line 40, in run
    result = self.fn(*self.args, **self.kwargs)
             ^^^^^^^^^^^^^^^^^^^^^^^^^^^^^^^^^^
  File "/usr/local/lib/python3.11/site-packages/asgiref/sync.py", line 493, in thread_handler
    return func(*args, **kwargs)
           ^^^^^^^^^^^^^^^^^^^^^
  File "/usr/local/lib/python3.11/site-packages/django/views/decorators/csrf.py", line 65, in _view_wrapper
    return view_func(request, *args, **kwargs)
           ^^^^^^^^^^^^^^^^^^^^^^^^^^^^^^^^^^^
  File "/usr/local/lib/python3.11/site-packages/django/views/generic/base.py", line 104, in view
    return self.dispatch(request, *args, **kwargs)
           ^^^^^^^^^^^^^^^^^^^^^^^^^^^^^^^^^^^^^^^
  File "/usr/local/lib/python3.11/site-packages/rest_framework/views.py", line 515, in dispatch
    response = self.handle_exception(exc)
               ^^^^^^^^^^^^^^^^^^^^^^^^^^
  File "/usr/local/lib/python3.11/site-packages/rest_framework/views.py", line 475, in handle_exception
    self.raise_uncaught_exception(exc)
  File "/usr/local/lib/python3.11/site-packages/rest_framework/views.py", line 486, in raise_uncaught_exception
    raise exc
  File "/usr/local/lib/python3.11/site-packages/rest_framework/views.py", line 512, in dispatch
    response = handler(request, *args, **kwargs)
               ^^^^^^^^^^^^^^^^^^^^^^^^^^^^^^^^^
  File "/usr/local/lib/python3.11/site-packages/rest_framework/decorators.py", line 50, in handler
    return func(*args, **kwargs)
           ^^^^^^^^^^^^^^^^^^^^^
TypeError: create_or_update_round_schedule() missing 1 required positional argument: 'pk'
[2025-08-12 05:53:41,026] WARNING django.request - Not Found: /schedule/create-scheduled-rounds/
[2025-08-12 05:53:54,388] WARNING django.request - Not Found: /schedule/create-scheduled-rounds/16/
[2025-08-12 05:58:27,234] WARNING django.request - Unauthorized: /schedule/create-scheduled-rounds/16/
[2025-08-12 06:04:09,239] WARNING django.request - Not Found: /schedule/create-scheduled-rounds/16/
[2025-08-12 06:04:17,068] WARNING django.request - Unauthorized: /schedule/update-scheduled-rounds/16/
[2025-08-12 06:04:33,083] WARNING django.request - Unsupported Media Type: /schedule/update-scheduled-rounds/16/
[2025-08-12 06:12:06,739] WARNING django.request - Unauthorized: /schedule/update-scheduled-rounds/16/
[2025-08-16 12:15:04,005] WARNING django.request - Not Found: /favicon.ico
